Workbook

Sheet ThongTin
A1: TRƯỜNG ĐẠI HỌC KHOA HỌC TỰ NHIÊN, ĐHQG-HCM – KHOA VẬT LÝ – VẬT LÝ KỸ THUẬT
A2: BIÊN BẢN GHI NHẬN SỐ LIỆU ĐO BỨC XẠ GAMMA
A3: Mã hồ sơ: THVLHĐ-GM-N3-01 | Bài: Phân bố thống kê trong phân rã phóng xạ | Nhóm 3
A5: Chú thích: | B5: Ô nền vàng | C5: → thông tin nhóm cần điền/xác nhận. Chữ xanh dương = số liệu nhập tay; chữ đen = công thức; chữ xanh lá = liên kết từ trang khác.
A7: I | B7: THÔNG TIN CHUNG
A8: 1 | B8: Học phần | C8: Thực hành Vật lý Hiện đại (THVLHĐ)
A9: 2 | B9: Tên bài thực tập | C9: Phân bố thống kê trong phân rã phóng xạ
A10: 3 | B10: Nhóm thực hiện | C10: Nhóm 3
A11: 4 | B11: Phòng thí nghiệm
A12: 5 | B12: Ngày đo
A13: 6 | B13: Giảng viên hướng dẫn
A14: 7 | B14: Mã hồ sơ | C14: THVLHĐ-GM-N3-01
A15: II | B15: THIẾT BỊ ĐO
A16: 1 | B16: Đầu dò | C16: Ống đếm Geiger–Müller (model/số hiệu: ……)
A17: 2 | B17: Bộ đếm (Counter) | C17: Model/số hiệu: ……
A18: 3 | B18: Nguồn cao thế (HV) | C18: Model/số hiệu: ……
A19: 4 | B19: Điện áp làm việc đặt cho GM (V)
A20: III | B20: NGUỒN PHÓNG XẠ
A21: 1 | B21: Đồng vị | C21: Ra-226 (dùng cho Bộ 2 và Bộ 3)
A22: 2 | B22: Hoạt độ / ngày chuẩn
A23: 3 | B23: Bộ 1 (mức thấp) | C23: Phông (“Font” trong số liệu gốc), xác nhận có/không đặt nguồn
A24: IV | B24: ĐIỀU KIỆN ĐO
A25: 1 | B25: Thời gian mỗi lần đo ngắn t (s) | C25: 10
A26: 2 | B26: Số lần đo ngắn mỗi bộ n | C26: 100
A27: 3 | B27: Thời gian phép đo dài T (s) | C27: 100
A28: 4 | B28: Khoảng cách nguồn–đầu dò Bộ 1 (cm)
A29: 5 | B29: Khoảng cách nguồn–đầu dò Bộ 2 (cm)
A30: 6 | B30: Khoảng cách nguồn–đầu dò Bộ 3 (cm)
A31: 7 | B31: Nhiệt độ / độ ẩm phòng
A32: V | B32: QUY ƯỚC BÁO CÁO
A33: 1 | B33: Độ không đảm bảo đo | C33: Chuẩn (k = 1, ~68%), thống kê đếm Poisson u(N) = √N
A34: 2 | B34: Số liệu gốc | C34: Tệp “nhóm 1.xlsx” (không chỉnh sửa)
A35: 3 | B35: Phân tích bổ trợ | C35: analysis.py (Python) – Monte Carlo, χ² Pearson, đồ thị
A37: VI. DANH SÁCH THÀNH VIÊN NHÓM 3
A38: STT | B38: Họ và tên | C38: MSSV | D38: Vai trò | E38: Chữ ký | F38: Ghi chú
A39: 1 | B39: Phạm Việt Linh | C39: 24130044 | D39: Thành viên
A40: 2 | B40: Lê Quốc Long | C40: 24130048 | D40: Thành viên
A41: 3 | B41: Ngô Đặng Tuấn Long | C41: 24130049 | D41: Thành viên
A42: 4 | B42: Dương Quốc Huy | C42: 24130103 | D42: Thành viên
A43: 5 | B43: Trần Trí Dũng | C43: 24130162 | D43: Thành viên
...

Sheet SoLieuTho
A1: TRƯỜNG ĐẠI HỌC KHOA HỌC TỰ NHIÊN, ĐHQG-HCM – KHOA VẬT LÝ – VẬT LÝ KỸ THUẬT
A2: BẢNG SỐ LIỆU ĐẾM THÔ – ỐNG ĐẾM GEIGER–MÜLLER
A3: Mã hồ sơ: THVLHĐ-GM-N3-01 | Bài: Phân bố thống kê trong phân rã phóng xạ | Nhóm 3
A6: N: số đếm ghi nhận trong thời gian t; u(N) = √N (k = 1); R = N/t (s⁻¹); u(R) = √N/t
A7: Lần đo j | B7: t (s) | C7: Bộ 1 – Mức thấp (Phông) | F7: Bộ 2 – Mức trung bình (Ra-226) | I7: Bộ 3 – Mức cao (Ra-226)
C8: N | D8: u(N) | E8: R (s⁻¹) | F8: N | G8: u(N) | H8: R (s⁻¹) | I8: N | J8: u(N) | K8: R (s⁻¹)
A9: 1 | B9: =ThongTin!$C$25 -> 10 | C9: 10 | D9: =SQRT(C9) -> 3.1622777 | E9: =C9/$B9 -> 1 | F9: 40 | G9: =SQRT(F9) -> 6.3245553 | H9: =F9/$B9 -> 4 | I9: 126 | J9: =SQRT(I9) -> 11.224972 | K9: =I9/$B9 -> 12.6
A10: 2 | B10: =ThongTin!$C$25 -> 10 | C10: 9 | D10: =SQRT(C10) -> 3 | E10: =C10/$B10 -> 0.9 | F10: 26 | G10: =SQRT(F10) -> 5.0990195 | H10: =F10/$B10 -> 2.6 | I10: 115 | J10: =SQRT(I10) -> 10.723805 | K10: =I10/$B10 -> 11.5
A11: 3 | B11: =ThongTin!$C$25 -> 10 | C11: 7 | D11: =SQRT(C11) -> 2.6457513 | E11: =C11/$B11 -> 0.7 | F11: 33 | G11: =SQRT(F11) -> 5.7445626 | H11: =F11/$B11 -> 3.3 | I11: 109 | J11: =SQRT(I11) -> 10.440307 | K11: =I11/$B11 -> 10.9
A12: 4 | B12: =ThongTin!$C$25 -> 10 | C12: 9 | D12: =SQRT(C12) -> 3 | E12: =C12/$B12 -> 0.9 | F12: 34 | G12: =SQRT(F12) -> 5.8309519 | H12: =F12/$B12 -> 3.4 | I12: 128 | J12: =SQRT(I12) -> 11.313708 | K12: =I12/$B12 -> 12.8
A13: 5 | B13: =ThongTin!$C$25 -> 10 | C13: 5 | D13: =SQRT(C13) -> 2.236068 | E13: =C13/$B13 -> 0.5 | F13: 37 | G13: =SQRT(F13) -> 6.0827625 | H13: =F13/$B13 -> 3.7 | I13: 134 | J13: =SQRT(I13) -> 11.575837 | K13: =I13/$B13 -> 13.4
A14: 6 | B14: =ThongTin!$C$25 -> 10 | C14: 7 | D14: =SQRT(C14) -> 2.6457513 | E14: =C14/$B14 -> 0.7 | F14: 46 | G14: =SQRT(F14) -> 6.78233 | H14: =F14/$B14 -> 4.6 | I14: 112 | J14: =SQRT(I14) -> 10.583005 | K14: =I14/$B14 -> 11.2
A15: 7 | B15: =ThongTin!$C$25 -> 10 | C15: 6 | D15: =SQRT(C15) -> 2.4494897 | E15: =C15/$B15 -> 0.6 | F15: 29 | G15: =SQRT(F15) -> 5.3851648 | H15: =F15/$B15 -> 2.9 | I15: 103 | J15: =SQRT(I15) -> 10.148892 | K15: =I15/$B15 -> 10.3
A16: 8 | B16: =ThongTin!$C$25 -> 10 | C16: 8 | D16: =SQRT(C16) -> 2.8284271 | E16: =C16/$B16 -> 0.8 | F16: 37 | G16: =SQRT(F16) -> 6.0827625 | H16: =F16/$B16 -> 3.7 | I16: 105 | J16: =SQRT(I16) -> 10.246951 | K16: =I16/$B16 -> 10.5
A17: 9 | B17: =ThongTin!$C$25 -> 10 | C17: 5 | D17: =SQRT(C17) -> 2.236068 | E17: =C17/$B17 -> 0.5 | F17: 33 | G17: =SQRT(F17) -> 5.7445626 | H17: =F17/$B17 -> 3.3 | I17: 104 | J17: =SQRT(I17) -> 10.198039 | K17: =I17/$B17 -> 10.4
A18: 10 | B18: =ThongTin!$C$25 -> 10 | C18: 4 | D18: =SQRT(C18) -> 2 | E18: =C18/$B18 -> 0.4 | F18: 33 | G18: =SQRT(F18) -> 5.7445626 | H18: =F18/$B18 -> 3.3 | I18: 115 | J18: =SQRT(I18) -> 10.723805 | K18: =I18/$B18 -> 11.5
A19: 11 | B19: =ThongTin!$C$25 -> 10 | C19: 6 | D19: =SQRT(C19) -> 2.4494897 | E19: =C19/$B19 -> 0.6 | F19: 43 | G19: =SQRT(F19) -> 6.5574385 | H19: =F19/$B19 -> 4.3 | I19: 100 | J19: =SQRT(I19) -> 10 | K19: =I19/$B19 -> 10
A20: 12 | B20: =ThongTin!$C$25 -> 10 | C20: 4 | D20: =SQRT(C20) -> 2 | E20: =C20/$B20 -> 0.4 | F20: 42 | G20: =SQRT(F20) -> 6.4807407 | H20: =F20/$B20 -> 4.2 | I20: 95 | J20: =SQRT(I20) -> 9.7467943 | K20: =I20/$B20 -> 9.5
... A108: 100 | B108: =ThongTin!$C$25 -> 10 | C108: 3 | D108: =SQRT(C108) -> 1.7320508 | E108: =C108/$B108 -> 0.3 | F108: 35 | G108: =SQRT(F108) -> 5.9160798 | H108: =F108/$B108 -> 3.5 | I108: 123 | J108: =SQRT(I108) -> 11.090537 | K108: =I108/$B108 -> 12.3
A110: PHÉP ĐO DÀI (một lần đo trong thời gian T)
A111: T | B111: =ThongTin!$C$27 -> 100 | C111: 45 | D111: =SQRT(C111) -> 6.7082039 | E111: =C111/$B111 -> 0.45 | F111: 437 | G111: =SQRT(F111) -> 20.904545 | H111: =F111/$B111 -> 4.37 | I111: 1085 | J111: =SQRT(I111) -> 32.939338 | K111: =I111/$B111 -> 10.85

Sheet ThongKe
A1: TRƯỜNG ĐẠI HỌC KHOA HỌC TỰ NHIÊN, ĐHQG-HCM – KHOA VẬT LÝ – VẬT LÝ KỸ THUẬT
A2: XỬ LÝ THỐNG KÊ SỐ LIỆU ĐẾM
A3: Mã hồ sơ: THVLHĐ-GM-N3-01 | Bài: Phân bố thống kê trong phân rã phóng xạ | Nhóm 3
A5: STT | B5: Đại lượng | C5: Bộ 1 – Mức thấp (Phông) | D5: Bộ 2 – Mức trung bình (Ra-226) | E5: Bộ 3 – Mức cao (Ra-226) | F5: Công thức / ghi chú
A6: A. ĐẶC TRƯNG THỐNG KÊ CỦA 100 LẦN ĐO 10 s
A7: 1 | B7: Số lần đo n | C7: =COUNT(SoLieuTho!$C$9:$C$108) -> 100 | D7: =COUNT(SoLieuTho!$F$9:$F$108) -> 100 | E7: =COUNT(SoLieuTho!$I$9:$I$108) -> 100 | F7: COUNT
A8: 2 | B8: Thời gian mỗi lần đo t (s) | C8: =ThongTin!$C$25 -> 10 | D8: =ThongTin!$C$25 -> 10 | E8: =ThongTin!$C$25 -> 10 | F8: Từ trang ThongTin
A9: 3 | B9: Tổng số đếm ΣN | C9: =SUM(SoLieuTho!$C$9:$C$108) -> 552 | D9: =SUM(SoLieuTho!$F$9:$F$108) -> 4122 | E9: =SUM(SoLieuTho!$I$9:$I$108) -> 11219 | F9: SUM
A10: 4 | B10: Số đếm trung bình x̄ | C10: =AVERAGE(SoLieuTho!$C$9:$C$108) -> 5.52 | D10: =AVERAGE(SoLieuTho!$F$9:$F$108) -> 41.22 | E10: =AVERAGE(SoLieuTho!$I$9:$I$108) -> 112.19 | F10: x̄ = ΣN/n
A11: 5 | B11: Độ lệch chuẩn thực nghiệm s | C11: =STDEV(SoLieuTho!$C$9:$C$108) -> 2.4637985 | D11: =STDEV(SoLieuTho!$F$9:$F$108) -> 7.0375329 | E11: =STDEV(SoLieuTho!$I$9:$I$108) -> 11.348203 | F11: STDEV (n − 1)
A12: 6 | B12: Phương sai s² | C12: =VAR(SoLieuTho!$C$9:$C$108) -> 6.070303 | D12: =VAR(SoLieuTho!$F$9:$F$108) -> 49.526869 | E12: =VAR(SoLieuTho!$I$9:$I$108) -> 128.78172 | F12: VAR (n − 1)
A13: 7 | B13: Độ không đảm bảo của trung bình u(x̄) | C13: =C11/SQRT(C7) -> 0.24637985 | D13: =D11/SQRT(D7) -> 0.70375329 | E13: =E11/SQRT(E7) -> 1.1348203 | F13: u(x̄) = s/√n
A14: 8 | B14: Độ lệch chuẩn Poisson lý thuyết σ = √x̄ | C14: =SQRT(C10) -> 2.349468 | D14: =SQRT(D10) -> 6.4202804 | E14: =SQRT(E10) -> 10.591978 | F14: σ_Poisson = √µ
A15: 9 | B15: Tỉ số s/√x̄ | C15: =C11/C14 -> 1.0486623 | D15: =D11/D14 -> 1.096141 | E15: =E11/E14 -> 1.071396 | F15: ≈ 1 nếu tuân theo Poisson
A16: 10 | B16: Chỉ số phân tán D = s²/x̄ | C16: =C12/C10 -> 1.0996926 | D16: =D12/D10 -> 1.2015252 | E16: =E12/E10 -> 1.1478894 | F16: Poisson: D = 1
A17: 11 | B17: Thống kê phân tán χ² = (n − 1)·D | C17: =(C7-1)*C16 -> 108.86957 | D17: =(D7-1)*D16 -> 118.95099 | E17: =(E7-1)*E16 -> 113.64106 | F17: Tuân theo χ²(n − 1)
A18: 12 | B18: p-value hai phía của kiểm định phân tán | C18: =2*MIN(CHIDIST(C17,C7-1),1-CHIDIST(C17,C7-1)) -> 0.46760639 | D18: =2*MIN(CHIDIST(D17,D7-1),1-CHIDIST(D17,D7-1)) -> 0.1678645 | E18: =2*MIN(CHIDIST(E17,E7-1),1-CHIDIST(E17,E7-1)) -> 0.29831169 | F18: p > 0,05: phương sai phù hợp Poisson
A19: 13 | B19: Kết luận về phương sai | C19: =IF(C18>0.05,"Phù hợp Poisson","Không phù hợp") -> Phù hợp Poisson | D19: =IF(D18>0.05,"Phù hợp Poisson","Không phù hợp") -> Phù hợp Poisson | E19: =IF(E18>0.05,"Phù hợp Poisson","Không phù hợp") -> Phù hợp Poisson
A20: 14 | B20: Tốc độ đếm trung bình R = x̄/t (s⁻¹) | C20: =C10/C8 -> 0.552 | D20: =D10/D8 -> 4.122 | E20: =E10/E8 -> 11.219
A21: 15 | B21: u(R) (s⁻¹) | C21: =C13/C8 -> 0.024637985 | D21: =D13/D8 -> 0.070375329 | E21: =E13/E8 -> 0.11348203 | F21: u(R) = u(x̄)/t
A22: B. SO SÁNH VỚI PHÉP ĐO DÀI T = 100 s
A23: 16 | B23: Số đếm phép đo dài N_T | C23: =SoLieuTho!$C$111 -> 45 | D23: =SoLieuTho!$F$111 -> 437 | E23: =SoLieuTho!$I$111 -> 1085 | F23: Từ trang SoLieuTho
A24: 17 | B24: Quy về 10 s: N_T·t/T | C24: =C23*C8/SoLieuTho!$B$111 -> 4.5 | D24: =D23*D8/SoLieuTho!$B$111 -> 43.7 | E24: =E23*E8/SoLieuTho!$B$111 -> 108.5
A25: 18 | B25: u(N_T·t/T) = √N_T·t/T | C25: =SQRT(C23)*C8/SoLieuTho!$B$111 -> 0.67082039 | D25: =SQRT(D23)*D8/SoLieuTho!$B$111 -> 2.0904545 | E25: =SQRT(E23)*E8/SoLieuTho!$B$111 -> 3.2939338
A26: 19 | B26: Độ lệch chuẩn dự đoán cho 10 s từ phép đo dài √(N_T·t/T) | C26: =SQRT(C24) -> 2.1213203 | D26: =SQRT(D24) -> 6.6105976 | E26: =SQRT(E24) -> 10.416333 | F26: So với s ở mục A
A27: 20 | B27: Hiệu Δ = N_T·t/T − x̄ | C27: =C24-C10 -> -1.02 | D27: =D24-D10 -> 2.48 | E27: =E24-E10 -> -3.69
A28: 21 | B28: u(Δ) = √(u(N_T·t/T)² + u(x̄)²) | C28: =SQRT(C25^2+C13^2) -> 0.71463489 | D28: =SQRT(D25^2+D13^2) -> 2.2057354 | E28: =SQRT(E25^2+E13^2) -> 3.483937
A29: 22 | B29: Chỉ số z = Δ/u(Δ) (số độ lệch chuẩn) | C29: =C27/C28 -> -1.4273023 | D29: =D27/D28 -> 1.1243416 | E29: =E27/E28 -> -1.0591466 | F29: |z| ≤ 2: phù hợp
A30: 23 | B30: Kết luận | C30: =IF(ABS(C29)<=2,"Phù hợp (|z| ≤ 2)","Không phù hợp") -> Phù hợp (|z| ≤ 2) | D30: =IF(ABS(D29)<=2,"Phù hợp (|z| ≤ 2)","Không phù hợp") -> Phù hợp (|z| ≤ 2) | E30: =IF(ABS(E29)<=2,"Phù hợp (|z| ≤ 2)","Không phù hợp") -> Phù hợp (|z| ≤ 2)
A31: C. ĐỘ LỆCH LỚN NHẤT SO VỚI TRUNG BÌNH
A32: 24 | B32: Giá trị lớn nhất | C32: =MAX(SoLieuTho!$C$9:$C$108) -> 12 | D32: =MAX(SoLieuTho!$F$9:$F$108) -> 58 | E32: =MAX(SoLieuTho!$I$9:$I$108) -> 139
A33: 25 | B33: Giá trị nhỏ nhất | C33: =MIN(SoLieuTho!$C$9:$C$108) -> 1 | D33: =MIN(SoLieuTho!$F$9:$F$108) -> 26 | E33: =MIN(SoLieuTho!$I$9:$I$108) -> 81
A34: 26 | B34: Độ lệch lớn nhất x − x̄ | C34: =IF(C32-C10>=C10-C33,C32-C10,C33-C10) -> 6.48 | D34: =IF(D32-D10>=D10-D33,D32-D10,D33-D10) -> 16.78 | E34: =IF(E32-E10>=E10-E33,E32-E10,E33-E10) -> -31.19
A35: 27 | B35: Tính theo σ = √x̄ | C35: =ABS(C34)/C14 -> 2.7580712 | D35: =ABS(D34)/D14 -> 2.613593 | E35: =ABS(E34)/E14 -> 2.9446813
A36: 28 | B36: Xác suất Poisson một lần đo lệch ít nhất như vậy (một phía) | C36: =IF(C34>=0,1-POISSON(C32-1,C10,TRUE()),POISSON(C33,C10,TRUE())) -> 0.011276268 | D36: =IF(D34>=0,1-POISSON(D32-1,D10,TRUE()),POISSON(D33,D10,TRUE())) -> 0.007846102 | E36: =IF(E34>=0,1-POISSON(E32-1,E10,TRUE()),POISSON(E33,E10,TRUE())) -> 0.0012194231 | F36: P(X ≥ max) hoặc P(X ≤ min)
A37: 29 | B37: Xác suất xuất hiện ít nhất 1 lần trong n lần đo | C37: =1-(1-C36)^C7 -> 0.67826682 | D37: =1-(1-D36)^D7 -> 0.54511219 | E37: =1-(1-E36)^E7 -> 0.11486643 | F37: 1 − (1 − p)ⁿ (n = 100 cơ hội)
A38: 30 | B38: Số lần kỳ vọng trong n lần đo | C38: =C7*C36 -> 1.1276268 | D38: =D7*D36 -> 0.7846102 | E38: =E7*E36 -> 0.12194231
A39: 31 | B39: Kết luận về hệ đếm | C39: =IF(C37>0.05,"Hoạt động bình thường","Cần kiểm tra") -> Hoạt động bình thường | D39: =IF(D37>0.05,"Hoạt động bình thường","Cần kiểm tra") -> Hoạt động bình thường | E39: =IF(E37>0.05,"Hoạt động bình thường","Cần kiểm tra") -> Hoạt động bình thường | F39: Ngưỡng 5%
A40: D. KIỂM ĐỊNH χ² (CÔNG THỨC 5): POISSON VÀ GAUSS
A41: 32 | B41: χ² Poisson | C41: =TanSuat!$F$26 -> 28.252044 | D41: =TanSuat!$M$54 -> 43.091911 | E41: =TanSuat!$T$85 -> 34.111204 | F41: Σ(O − E)²/O, O > 0
...

Sheet TanSuat
A1: TRƯỜNG ĐẠI HỌC KHOA HỌC TỰ NHIÊN, ĐHQG-HCM – KHOA VẬT LÝ – VẬT LÝ KỸ THUẬT
A2: BẢNG TẦN SUẤT SỐ ĐẾM VÀ PHÂN BỐ LÝ THUYẾT
A3: Mã hồ sơ: THVLHĐ-GM-N3-01 | Bài: Phân bố thống kê trong phân rã phóng xạ | Nhóm 3
A4: O: số lần xuất hiện; u(O) = √O; E: tần suất lý thuyết = n·P(k); χ² theo công thức (5): (O − E)²/O, chỉ tính các bin O > 0
A6: Bộ 1 – Mức thấp (Phông) | H6: Bộ 2 – Mức trung bình (Ra-226) | O6: Bộ 3 – Mức cao (Ra-226)
A7: x̄ = | B7: =ThongKe!$C$10 -> 5.52 | D7: n = | E7: =COUNT(SoLieuTho!$C$9:$C$108) -> 100 | H7: x̄ = | I7: =ThongKe!$D$10 -> 41.22 | K7: n = | L7: =COUNT(SoLieuTho!$F$9:$F$108) -> 100 | O7: x̄ = | P7: =ThongKe!$E$10 -> 112.19 | R7: n = | S7: =COUNT(SoLieuTho!$I$9:$I$108) -> 100
A8: k | B8: O | C8: u(O) | D8: E Poisson | E8: E Gauss | F8: χ² Poisson | G8: χ² Gauss | H8: k | I8: O | J8: u(O) | K8: E Poisson | L8: E Gauss | M8: χ² Poisson | N8: χ² Gauss | O8: k | P8: O | Q8: u(O) | R8: E Poisson | S8: E Gauss | T8: χ² Poisson | U8: χ² Gauss
A9: 0 | B9: =COUNTIF(SoLieuTho!$C$9:$C$108,A9) -> 0 | C9: =SQRT(B9) -> 0 | D9: =$E$7*POISSON(A9,$B$7,FALSE()) -> 0.40058479 | E9: =$E$7*NORMDIST(A9,$B$7,SQRT($B$7),FALSE()) -> 1.0747013 | F9: =IF(B9>0,(B9-D9)^2/B9,0) -> 0 | G9: =IF(B9>0,(B9-E9)^2/B9,0) -> 0 | H9: 20 | I9: =COUNTIF(SoLieuTho!$F$9:$F$108,H9) -> 0 | J9: =SQRT(I9) -> 0 | K9: =$L$7*POISSON(H9,$I$7,FALSE()) -> 0.010337525 | L9: =$L$7*NORMDIST(H9,$I$7,SQRT($I$7),FALSE()) -> 0.026377505 | M9: =IF(I9>0,(I9-K9)^2/I9,0) -> 0 | N9: =IF(I9>0,(I9-L9)^2/I9,0) -> 0 | O9: 75 | P9: =COUNTIF(SoLieuTho!$I$9:$I$108,O9) -> 0 | Q9: =SQRT(P9) -> 0 | R9: =$S$7*POISSON(O9,$P$7,FALSE()) -> 0.0042506119 | S9: =$S$7*NORMDIST(O9,$P$7,SQRT($P$7),FALSE()) -> 0.0079233236 | T9: =IF(P9>0,(P9-R9)^2/P9,0) -> 0 | U9: =IF(P9>0,(P9-S9)^2/P9,0) -> 0
A10: 1 | B10: =COUNTIF(SoLieuTho!$C$9:$C$108,A10) -> 4 | C10: =SQRT(B10) -> 2 | D10: =$E$7*POISSON(A10,$B$7,FALSE()) -> 2.2112281 | E10: =$E$7*NORMDIST(A10,$B$7,SQRT($B$7),FALSE()) -> 2.6683572 | F10: =IF(B10>0,(B10-D10)^2/B10,0) -> 0.79992626 | G10: =IF(B10>0,(B10-E10)^2/B10,0) -> 0.44331812 | H10: 21 | I10: =COUNTIF(SoLieuTho!$F$9:$F$108,H10) -> 0 | J10: =SQRT(I10) -> 0 | K10: =$L$7*POISSON(H10,$I$7,FALSE()) -> 0.020291085 | L10: =$L$7*NORMDIST(H10,$I$7,SQRT($I$7),FALSE()) -> 0.043605364 | M10: =IF(I10>0,(I10-K10)^2/I10,0) -> 0 | N10: =IF(I10>0,(I10-L10)^2/I10,0) -> 0 | O10: 76 | P10: =COUNTIF(SoLieuTho!$I$9:$I$108,O10) -> 0 | Q10: =SQRT(P10) -> 0 | R10: =$S$7*POISSON(O10,$P$7,FALSE()) -> 0.0062746862 | S10: =$S$7*NORMDIST(O10,$P$7,SQRT($P$7),FALSE()) -> 0.010988456 | T10: =IF(P10>0,(P10-R10)^2/P10,0) -> 0 | U10: =IF(P10>0,(P10-S10)^2/P10,0) -> 0
A11: 2 | B11: =COUNTIF(SoLieuTho!$C$9:$C$108,A11) -> 8 | C11: =SQRT(B11) -> 2.8284271 | D11: =$E$7*POISSON(A11,$B$7,FALSE()) -> 6.1029895 | E11: =$E$7*NORMDIST(A11,$B$7,SQRT($B$7),FALSE()) -> 5.527435 | F11: =IF(B11>0,(B11-D11)^2/B11,0) -> 0.44983113 | G11: =IF(B11>0,(B11-E11)^2/B11,0) -> 0.76419718 | H11: 22 | I11: =COUNTIF(SoLieuTho!$F$9:$F$108,H11) -> 0 | J11: =SQRT(I11) -> 0 | K11: =$L$7*POISSON(H11,$I$7,FALSE()) -> 0.038018116 | L11: =$L$7*NORMDIST(H11,$I$7,SQRT($I$7),FALSE()) -> 0.070357452 | M11: =IF(I11>0,(I11-K11)^2/I11,0) -> 0 | N11: =IF(I11>0,(I11-L11)^2/I11,0) -> 0 | O11: 77 | P11: =COUNTIF(SoLieuTho!$I$9:$I$108,O11) -> 0 | Q11: =SQRT(P11) -> 0 | R11: =$S$7*POISSON(O11,$P$7,FALSE()) -> 0.0091422992 | S11: =$S$7*NORMDIST(O11,$P$7,SQRT($P$7),FALSE()) -> 0.015104101 | T11: =IF(P11>0,(P11-R11)^2/P11,0) -> 0 | U11: =IF(P11>0,(P11-S11)^2/P11,0) -> 0
A12: 3 | B12: =COUNTIF(SoLieuTho!$C$9:$C$108,A12) -> 9 | C12: =SQRT(B12) -> 3 | D12: =$E$7*POISSON(A12,$B$7,FALSE()) -> 11.229501 | E12: =$E$7*NORMDIST(A12,$B$7,SQRT($B$7),FALSE()) -> 9.5527143 | F12: =IF(B12>0,(B12-D12)^2/B12,0) -> 0.55229699 | G12: =IF(B12>0,(B12-E12)^2/B12,0) -> 0.033943674 | H12: 23 | I12: =COUNTIF(SoLieuTho!$F$9:$F$108,H12) -> 0 | J12: =SQRT(I12) -> 0 | K12: =$L$7*POISSON(H12,$I$7,FALSE()) -> 0.068135075 | L12: =$L$7*NORMDIST(H12,$I$7,SQRT($I$7),FALSE()) -> 0.11080115 | M12: =IF(I12>0,(I12-K12)^2/I12,0) -> 0 | N12: =IF(I12>0,(I12-L12)^2/I12,0) -> 0 | O12: 78 | P12: =COUNTIF(SoLieuTho!$I$9:$I$108,O12) -> 0 | Q12: =SQRT(P12) -> 0 | R12: =$S$7*POISSON(O12,$P$7,FALSE()) -> 0.013149674 | S12: =$S$7*NORMDIST(O12,$P$7,SQRT($P$7),FALSE()) -> 0.020576999 | T12: =IF(P12>0,(P12-R12)^2/P12,0) -> 0 | U12: =IF(P12>0,(P12-S12)^2/P12,0) -> 0
A13: 4 | B13: =COUNTIF(SoLieuTho!$C$9:$C$108,A13) -> 14 | C13: =SQRT(B13) -> 3.7416574 | D13: =$E$7*POISSON(A13,$B$7,FALSE()) -> 15.496711 | E13: =$E$7*NORMDIST(A13,$B$7,SQRT($B$7),FALSE()) -> 13.773788 | F13: =IF(B13>0,(B13-D13)^2/B13,0) -> 0.16001024 | G13: =IF(B13>0,(B13-E13)^2/B13,0) -> 0.0036551359 | H13: 24 | I13: =COUNTIF(SoLieuTho!$F$9:$F$108,H13) -> 0 | J13: =SQRT(I13) -> 0 | K13: =$L$7*POISSON(H13,$I$7,FALSE()) -> 0.11702199 | L13: =$L$7*NORMDIST(H13,$I$7,SQRT($I$7),FALSE()) -> 0.1703109 | M13: =IF(I13>0,(I13-K13)^2/I13,0) -> 0 | N13: =IF(I13>0,(I13-L13)^2/I13,0) -> 0 | O13: 79 | P13: =COUNTIF(SoLieuTho!$I$9:$I$108,O13) -> 0 | Q13: =SQRT(P13) -> 0 | R13: =$S$7*POISSON(O13,$P$7,FALSE()) -> 0.018674201 | S13: =$S$7*NORMDIST(O13,$P$7,SQRT($P$7),FALSE()) -> 0.027784215 | T13: =IF(P13>0,(P13-R13)^2/P13,0) -> 0 | U13: =IF(P13>0,(P13-S13)^2/P13,0) -> 0
A14: 5 | B14: =COUNTIF(SoLieuTho!$C$9:$C$108,A14) -> 14 | C14: =SQRT(B14) -> 3.7416574 | D14: =$E$7*POISSON(A14,$B$7,FALSE()) -> 17.108369 | E14: =$E$7*NORMDIST(A14,$B$7,SQRT($B$7),FALSE()) -> 16.569273 | F14: =IF(B14>0,(B14-D14)^2/B14,0) -> 0.69013974 | G14: =IF(B14>0,(B14-E14)^2/B14,0) -> 0.47151178 | H14: 25 | I14: =COUNTIF(SoLieuTho!$F$9:$F$108,H14) -> 0 | J14: =SQRT(I14) -> 0 | K14: =$L$7*POISSON(H14,$I$7,FALSE()) -> 0.19294586 | L14: =$L$7*NORMDIST(H14,$I$7,SQRT($I$7),FALSE()) -> 0.25550805 | M14: =IF(I14>0,(I14-K14)^2/I14,0) -> 0 | N14: =IF(I14>0,(I14-L14)^2/I14,0) -> 0 | O14: 80 | P14: =COUNTIF(SoLieuTho!$I$9:$I$108,O14) -> 0 | Q14: =SQRT(P14) -> 0 | R14: =$S$7*POISSON(O14,$P$7,FALSE()) -> 0.026188233 | S14: =$S$7*NORMDIST(O14,$P$7,SQRT($P$7),FALSE()) -> 0.037182891 | T14: =IF(P14>0,(P14-R14)^2/P14,0) -> 0 | U14: =IF(P14>0,(P14-S14)^2/P14,0) -> 0
A15: 6 | B15: =COUNTIF(SoLieuTho!$C$9:$C$108,A15) -> 21 | C15: =SQRT(B15) -> 4.5825757 | D15: =$E$7*POISSON(A15,$B$7,FALSE()) -> 15.739699 | E15: =$E$7*NORMDIST(A15,$B$7,SQRT($B$7),FALSE()) -> 16.629416 | F15: =IF(B15>0,(B15-D15)^2/B15,0) -> 1.3176554 | G15: =IF(B15>0,(B15-E15)^2/B15,0) -> 0.90961939 | H15: 26 | I15: =COUNTIF(SoLieuTho!$F$9:$F$108,H15) -> 1 | J15: =SQRT(I15) -> 1 | K15: =$L$7*POISSON(H15,$I$7,FALSE()) -> 0.3058934 | L15: =$L$7*NORMDIST(H15,$I$7,SQRT($I$7),FALSE()) -> 0.37413705 | M15: =IF(I15>0,(I15-K15)^2/I15,0) -> 0.48178398 | N15: =IF(I15>0,(I15-L15)^2/I15,0) -> 0.39170443 | O15: 81 | P15: =COUNTIF(SoLieuTho!$I$9:$I$108,O15) -> 1 | Q15: =SQRT(P15) -> 1 | R15: =$S$7*POISSON(O15,$P$7,FALSE()) -> 0.036272319 | S15: =$S$7*NORMDIST(O15,$P$7,SQRT($P$7),FALSE()) -> 0.049319324 | T15: =IF(P15>0,(P15-R15)^2/P15,0) -> 0.92877104 | U15: =IF(P15>0,(P15-S15)^2/P15,0) -> 0.90379375
A16: 7 | B16: =COUNTIF(SoLieuTho!$C$9:$C$108,A16) -> 13 | C16: =SQRT(B16) -> 3.6055513 | D16: =$E$7*POISSON(A16,$B$7,FALSE()) -> 12.411877 | E16: =$E$7*NORMDIST(A16,$B$7,SQRT($B$7),FALSE()) -> 13.92432 | F16: =IF(B16>0,(B16-D16)^2/B16,0) -> 0.026606809 | G16: =IF(B16>0,(B16-E16)^2/B16,0) -> 0.065720522 | H16: 27 | I16: =COUNTIF(SoLieuTho!$F$9:$F$108,H16) -> 0 | J16: =SQRT(I16) -> 0 | K16: =$L$7*POISSON(H16,$I$7,FALSE()) -> 0.46699725 | L16: =$L$7*NORMDIST(H16,$I$7,SQRT($I$7),FALSE()) -> 0.53471312 | M16: =IF(I16>0,(I16-K16)^2/I16,0) -> 0 | N16: =IF(I16>0,(I16-L16)^2/I16,0) -> 0 | O16: 82 | P16: =COUNTIF(SoLieuTho!$I$9:$I$108,O16) -> 0 | Q16: =SQRT(P16) -> 0 | R16: =$S$7*POISSON(O16,$P$7,FALSE()) -> 0.049626725 | S16: =$S$7*NORMDIST(O16,$P$7,SQRT($P$7),FALSE()) -> 0.064836568 | T16: =IF(P16>0,(P16-R16)^2/P16,0) -> 0 | U16: =IF(P16>0,(P16-S16)^2/P16,0) -> 0
A17: 8 | B17: =COUNTIF(SoLieuTho!$C$9:$C$108,A17) -> 2 | C17: =SQRT(B17) -> 1.4142136 | D17: =$E$7*POISSON(A17,$B$7,FALSE()) -> 8.5641952 | E17: =$E$7*NORMDIST(A17,$B$7,SQRT($B$7),FALSE()) -> 9.7273477 | F17: =IF(B17>0,(B17-D17)^2/B17,0) -> 21.544329 | G17: =IF(B17>0,(B17-E17)^2/B17,0) -> 29.855952 | H17: 28 | I17: =COUNTIF(SoLieuTho!$F$9:$F$108,H17) -> 1 | J17: =SQRT(I17) -> 1 | K17: =$L$7*POISSON(H17,$I$7,FALSE()) -> 0.68748667 | L17: =$L$7*NORMDIST(H17,$I$7,SQRT($I$7),FALSE()) -> 0.74589028 | M17: =IF(I17>0,(I17-K17)^2/I17,0) -> 0.097664581 | N17: =IF(I17>0,(I17-L17)^2/I17,0) -> 0.064571748 | O17: 83 | P17: =COUNTIF(SoLieuTho!$I$9:$I$108,O17) -> 0 | Q17: =SQRT(P17) -> 0 | R17: =$S$7*POISSON(O17,$P$7,FALSE()) -> 0.067079787 | S17: =$S$7*NORMDIST(O17,$P$7,SQRT($P$7),FALSE()) -> 0.084479602 | T17: =IF(P17>0,(P17-R17)^2/P17,0) -> 0 | U17: =IF(P17>0,(P17-S17)^2/P17,0) -> 0
A18: 9 | B18: =COUNTIF(SoLieuTho!$C$9:$C$108,A18) -> 8 | C18: =SQRT(B18) -> 2.8284271 | D18: =$E$7*POISSON(A18,$B$7,FALSE()) -> 5.2527064 | E18: =$E$7*NORMDIST(A18,$B$7,SQRT($B$7),FALSE()) -> 5.6694165 | F18: =IF(B18>0,(B18-D18)^2/B18,0) -> 0.94345277 | G18: =IF(B18>0,(B18-E18)^2/B18,0) -> 0.67895244 | H18: 29 | I18: =COUNTIF(SoLieuTho!$F$9:$F$108,H18) -> 3 | J18: =SQRT(I18) -> 1.7320508 | K18: =$L$7*POISSON(H18,$I$7,FALSE()) -> 0.97717933 | L18: =$L$7*NORMDIST(H18,$I$7,SQRT($I$7),FALSE()) -> 1.0155307 | M18: =IF(I18>0,(I18-K18)^2/I18,0) -> 1.3639345 | N18: =IF(I18>0,(I18-L18)^2/I18,0) -> 1.3127062 | O18: 84 | P18: =COUNTIF(SoLieuTho!$I$9:$I$108,O18) -> 1 | Q18: =SQRT(P18) -> 1 | R18: =$S$7*POISSON(O18,$P$7,FALSE()) -> 0.089591444 | S18: =$S$7*NORMDIST(O18,$P$7,SQRT($P$7),FALSE()) -> 0.10909696 | T18: =IF(P18>0,(P18-R18)^2/P18,0) -> 0.82884374 | U18: =IF(P18>0,(P18-S18)^2/P18,0) -> 0.79370823
A19: 10 | B19: =COUNTIF(SoLieuTho!$C$9:$C$108,A19) -> 5 | C19: =SQRT(B19) -> 2.236068 | D19: =$E$7*POISSON(A19,$B$7,FALSE()) -> 2.8994939 | E19: =$E$7*NORMDIST(A19,$B$7,SQRT($B$7),FALSE()) -> 2.7568031 | F19: =IF(B19>0,(B19-D19)^2/B19,0) -> 0.88242515 | G19: =IF(B19>0,(B19-E19)^2/B19,0) -> 1.0063865 | H19: 30 | I19: =COUNTIF(SoLieuTho!$F$9:$F$108,H19) -> 1 | J19: =SQRT(I19) -> 1 | K19: =$L$7*POISSON(H19,$I$7,FALSE()) -> 1.3426444 | L19: =$L$7*NORMDIST(H19,$I$7,SQRT($I$7),FALSE()) -> 1.3495069 | M19: =IF(I19>0,(I19-K19)^2/I19,0) -> 0.11740518 | N19: =IF(I19>0,(I19-L19)^2/I19,0) -> 0.1221551 | O19: 85 | P19: =COUNTIF(SoLieuTho!$I$9:$I$108,O19) -> 0 | Q19: =SQRT(P19) -> 0 | R19: =$S$7*POISSON(O19,$P$7,FALSE()) -> 0.11825017 | S19: =$S$7*NORMDIST(O19,$P$7,SQRT($P$7),FALSE()) -> 0.13963759 | T19: =IF(P19>0,(P19-R19)^2/P19,0) -> 0 | U19: =IF(P19>0,(P19-S19)^2/P19,0) -> 0
A20: 11 | B20: =COUNTIF(SoLieuTho!$C$9:$C$108,A20) -> 0 | C20: =SQRT(B20) -> 0 | D20: =$E$7*POISSON(A20,$B$7,FALSE()) -> 1.4550188 | E20: =$E$7*NORMDIST(A20,$B$7,SQRT($B$7),FALSE()) -> 1.1183985 | F20: =IF(B20>0,(B20-D20)^2/B20,0) -> 0 | G20: =IF(B20>0,(B20-E20)^2/B20,0) -> 0 | H20: 31 | I20: =COUNTIF(SoLieuTho!$F$9:$F$108,H20) -> 1 | J20: =SQRT(I20) -> 1 | K20: =$L$7*POISSON(H20,$I$7,FALSE()) -> 1.7852839 | L20: =$L$7*NORMDIST(H20,$I$7,SQRT($I$7),FALSE()) -> 1.750335 | M20: =IF(I20>0,(I20-K20)^2/I20,0) -> 0.61667086 | N20: =IF(I20>0,(I20-L20)^2/I20,0) -> 0.56300268 | O20: 86 | P20: =COUNTIF(SoLieuTho!$I$9:$I$108,O20) -> 1 | Q20: =SQRT(P20) -> 1 | R20: =$S$7*POISSON(O20,$P$7,FALSE()) -> 0.15426147 | S20: =$S$7*NORMDIST(O20,$P$7,SQRT($P$7),FALSE()) -> 0.17714178 | T20: =IF(P20>0,(P20-R20)^2/P20,0) -> 0.71527367 | U20: =IF(P20>0,(P20-S20)^2/P20,0) -> 0.67709565
... A25: 16 | B25: =COUNTIF(SoLieuTho!$C$9:$C$108,A25) -> 0 | C25: =SQRT(B25) -> 0 | D25: =$E$7*POISSON(A25,$B$7,FALSE()) -> 0.014226567 | E25: =$E$7*NORMDIST(A25,$B$7,SQRT($B$7),FALSE()) -> 0.00081171353 | F25: =IF(B25>0,(B25-D25)^2/B25,0) -> 0 | G25: =IF(B25>0,(B25-E25)^2/B25,0) -> 0 | H25: 36 | I25: =COUNTIF(SoLieuTho!$F$9:$F$108,H25) -> 4 | J25: =SQRT(I25) -> 2 | K25: =$L$7*POISSON(H25,$I$7,FALSE()) -> 4.6960624 | L25: =$L$7*NORMDIST(H25,$I$7,SQRT($I$7),FALSE()) -> 4.4648957 | M25: =IF(I25>0,(I25-K25)^2/I25,0) -> 0.1211257 | N25: =IF(I25>0,(I25-L25)^2/I25,0) -> 0.054031996 | O25: 91 | P25: =COUNTIF(SoLieuTho!$I$9:$I$108,O25) -> 0 | Q25: =SQRT(P25) -> 0 | R25: =$S$7*POISSON(O25,$P$7,FALSE()) -> 0.49130633 | S25: =$S$7*NORMDIST(O25,$P$7,SQRT($P$7),FALSE()) -> 0.50915304 | T25: =IF(P25>0,(P25-R25)^2/P25,0) -> 0 | U25: =IF(P25>0,(P25-S25)^2/P25,0) -> 0
A26: Σ | B26: =SUM(B9:B25) -> 100 | D26: =SUM(D9:D25) -> 99.993399 | E26: =SUM(E9:E25) -> 99.508347 | F26: =SUM(F9:F25) -> 28.252044 | G26: =SUM(G9:G25) -> 35.547824 | H26: 37 | I26: =COUNTIF(SoLieuTho!$F$9:$F$108,H26) -> 5 | J26: =SQRT(I26) -> 2.236068 | K26: =$L$7*POISSON(H26,$I$7,FALSE()) -> 5.2316673 | L26: =$L$7*NORMDIST(H26,$I$7,SQRT($I$7),FALSE()) -> 5.0065816 | M26: =IF(I26>0,(I26-K26)^2/I26,0) -> 0.010733948 | N26: =IF(I26>0,(I26-L26)^2/I26,0) -> 8.6635097e-06 | O26: 92 | P26: =COUNTIF(SoLieuTho!$I$9:$I$108,O26) -> 0 | Q26: =SQRT(P26) -> 0 | R26: =$S$7*POISSON(O26,$P$7,FALSE()) -> 0.59912671 | S26: =$S$7*NORMDIST(O26,$P$7,SQRT($P$7),FALSE()) -> 0.61226667 | T26: =IF(P26>0,(P26-R26)^2/P26,0) -> 0 | U26: =IF(P26>0,(P26-S26)^2/P26,0) -> 0
A27: bin | B27: =COUNTIF(B9:B25,">0") -> 11 | H27: 38 | I27: =COUNTIF(SoLieuTho!$F$9:$F$108,H27) -> 4 | J27: =SQRT(I27) -> 2 | K27: =$L$7*POISSON(H27,$I$7,FALSE()) -> 5.6749823 | L27: =$L$7*NORMDIST(H27,$I$7,SQRT($I$7),FALSE()) -> 5.4794286 | M27: =IF(I27>0,(I27-K27)^2/I27,0) -> 0.7013914 | N27: =IF(I27>0,(I27-L27)^2/I27,0) -> 0.54717723 | O27: 93 | P27: =COUNTIF(SoLieuTho!$I$9:$I$108,O27) -> 1 | Q27: =SQRT(P27) -> 1 | R27: =$S$7*POISSON(O27,$P$7,FALSE()) -> 0.72275297 | S27: =$S$7*NORMDIST(O27,$P$7,SQRT($P$7),FALSE()) -> 0.72972939 | T27: =IF(P27>0,(P27-R27)^2/P27,0) -> 0.076865917 | U27: =IF(P27>0,(P27-S27)^2/P27,0) -> 0.073046205
H28: 39 | I28: =COUNTIF(SoLieuTho!$F$9:$F$108,H28) -> 7 | J28: =SQRT(I28) -> 2.6457513 | K28: =$L$7*POISSON(H28,$I$7,FALSE()) -> 5.9980197 | L28: =$L$7*NORMDIST(H28,$I$7,SQRT($I$7),FALSE()) -> 5.8531982 | M28: =IF(I28>0,(I28-K28)^2/I28,0) -> 0.1434235 | N28: =IF(I28>0,(I28-L28)^2/I28,0) -> 0.18787921 | O28: 94 | P28: =COUNTIF(SoLieuTho!$I$9:$I$108,O28) -> 3 | Q28: =SQRT(P28) -> 1.7320508 | R28: =$S$7*POISSON(O28,$P$7,FALSE()) -> 0.86261335 | S28: =$S$7*NORMDIST(O28,$P$7,SQRT($P$7),FALSE()) -> 0.86200938 | T28: =IF(P28>0,(P28-R28)^2/P28,0) -> 1.5228072 | U28: =IF(P28>0,(P28-S28)^2/P28,0) -> 1.523668
H29: 40 | I29: =COUNTIF(SoLieuTho!$F$9:$F$108,H29) -> 5 | J29: =SQRT(I29) -> 2.236068 | K29: =$L$7*POISSON(H29,$I$7,FALSE()) -> 6.1809593 | L29: =$L$7*NORMDIST(H29,$I$7,SQRT($I$7),FALSE()) -> 6.1026037 | M29: =IF(I29>0,(I29-K29)^2/I29,0) -> 0.27893298 | N29: =IF(I29>0,(I29-L29)^2/I29,0) -> 0.243147 | O29: 95 | P29: =COUNTIF(SoLieuTho!$I$9:$I$108,O29) -> 2 | Q29: =SQRT(P29) -> 1.4142136 | R29: =$S$7*POISSON(O29,$P$7,FALSE()) -> 1.018701 | S29: =$S$7*NORMDIST(O29,$P$7,SQRT($P$7),FALSE()) -> 1.0092322 | T29: =IF(P29>0,(P29-R29)^2/P29,0) -> 0.48147389 | U29: =IF(P29>0,(P29-S29)^2/P29,0) -> 0.49081045
H30: 41 | I30: =COUNTIF(SoLieuTho!$F$9:$F$108,H30) -> 3 | J30: =SQRT(I30) -> 1.7320508 | K30: =$L$7*POISSON(H30,$I$7,FALSE()) -> 6.2141254 | L30: =$L$7*NORMDIST(H30,$I$7,SQRT($I$7),FALSE()) -> 6.2101358 | M30: =IF(I30>0,(I30-K30)^2/I30,0) -> 3.4435341 | N30: =IF(I30>0,(I30-L30)^2/I30,0) -> 3.4349907 | O30: 96 | P30: =COUNTIF(SoLieuTho!$I$9:$I$108,O30) -> 0 | Q30: =SQRT(P30) -> 0 | R30: =$S$7*POISSON(O30,$P$7,FALSE()) -> 1.1905006 | S30: =$S$7*NORMDIST(O30,$P$7,SQRT($P$7),FALSE()) -> 1.1711138 | T30: =IF(P30>0,(P30-R30)^2/P30,0) -> 0 | U30: =IF(P30>0,(P30-S30)^2/P30,0) -> 0
H31: 42 | I31: =COUNTIF(SoLieuTho!$F$9:$F$108,H31) -> 6 | J31: =SQRT(I31) -> 2.4494897 | K31: =$L$7*POISSON(H31,$I$7,FALSE()) -> 6.0987203 | L31: =$L$7*NORMDIST(H31,$I$7,SQRT($I$7),FALSE()) -> 6.1680945 | M31: =IF(I31>0,(I31-K31)^2/I31,0) -> 0.0016242816 | N31: =IF(I31>0,(I31-L31)^2/I31,0) -> 0.0047092918 | O31: 97 | P31: =COUNTIF(SoLieuTho!$I$9:$I$108,O31) -> 2 | Q31: =SQRT(P31) -> 1.4142136 | R31: =$S$7*POISSON(O31,$P$7,FALSE()) -> 1.3769306 | S31: =$S$7*NORMDIST(O31,$P$7,SQRT($P$7),FALSE()) -> 1.3469023 | T31: =IF(P31>0,(P31-R31)^2/P31,0) -> 0.19410774 | U31: =IF(P31>0,(P31-S31)^2/P31,0) -> 0.21326833
H32: 43 | I32: =COUNTIF(SoLieuTho!$F$9:$F$108,H32) -> 3 | J32: =SQRT(I32) -> 1.7320508 | K32: =$L$7*POISSON(H32,$I$7,FALSE()) -> 5.8462616 | L32: =$L$7*NORMDIST(H32,$I$7,SQRT($I$7),FALSE()) -> 5.9795007 | M32: =IF(I32>0,(I32-K32)^2/I32,0) -> 2.7004017 | N32: =IF(I32>0,(I32-L32)^2/I32,0) -> 2.9591414 | O32: 98 | P32: =COUNTIF(SoLieuTho!$I$9:$I$108,O32) -> 1 | Q32: =SQRT(P32) -> 1 | R32: =$S$7*POISSON(O32,$P$7,FALSE()) -> 1.5763045 | S32: =$S$7*NORMDIST(O32,$P$7,SQRT($P$7),FALSE()) -> 1.5353309 | T32: =IF(P32>0,(P32-R32)^2/P32,0) -> 0.3321269 | U32: =IF(P32>0,(P32-S32)^2/P32,0) -> 0.28657915
H33: 44 | I33: =COUNTIF(SoLieuTho!$F$9:$F$108,H33) -> 1 | J33: =SQRT(I33) -> 1 | K33: =$L$7*POISSON(H33,$I$7,FALSE()) -> 5.4768842 | L33: =$L$7*NORMDIST(H33,$I$7,SQRT($I$7),FALSE()) -> 5.6577377 | M33: =IF(I33>0,(I33-K33)^2/I33,0) -> 20.042492 | N33: =IF(I33>0,(I33-L33)^2/I33,0) -> 21.69452 | O33: 99 | P33: =COUNTIF(SoLieuTho!$I$9:$I$108,O33) -> 0 | Q33: =SQRT(P33) -> 0 | R33: =$S$7*POISSON(O33,$P$7,FALSE()) -> 1.7863192 | S33: =$S$7*NORMDIST(O33,$P$7,SQRT($P$7),FALSE()) -> 1.73459 | T33: =IF(P33>0,(P33-R33)^2/P33,0) -> 0 | U33: =IF(P33>0,(P33-S33)^2/P33,0) -> 0
H34: 45 | I34: =COUNTIF(SoLieuTho!$F$9:$F$108,H34) -> 6 | J34: =SQRT(I34) -> 2.4494897 | K34: =$L$7*POISSON(H34,$I$7,FALSE()) -> 5.0168259 | L34: =$L$7*NORMDIST(H34,$I$7,SQRT($I$7),FALSE()) -> 5.2249806 | M34: =IF(I34>0,(I34-K34)^2/I34,0) -> 0.16110522 | N34: =IF(I34>0,(I34-L34)^2/I34,0) -> 0.10010917 | O34: 100 | P34: =COUNTIF(SoLieuTho!$I$9:$I$108,O34) -> 1 | Q34: =SQRT(P34) -> 1 | R34: =$S$7*POISSON(O34,$P$7,FALSE()) -> 2.0040715 | S34: =$S$7*NORMDIST(O34,$P$7,SQRT($P$7),FALSE()) -> 1.9423192 | T34: =IF(P34>0,(P34-R34)^2/P34,0) -> 1.0081597 | U34: =IF(P34>0,(P34-S34)^2/P34,0) -> 0.88796553
H35: 46 | I35: =COUNTIF(SoLieuTho!$F$9:$F$108,H35) -> 6 | J35: =SQRT(I35) -> 2.4494897 | K35: =$L$7*POISSON(H35,$I$7,FALSE()) -> 4.4955123 | L35: =$L$7*NORMDIST(H35,$I$7,SQRT($I$7),FALSE()) -> 4.7096707 | M35: =IF(I35>0,(I35-K35)^2/I35,0) -> 0.37724723 | N35: =IF(I35>0,(I35-L35)^2/I35,0) -> 0.2774916 | O35: 101 | P35: =COUNTIF(SoLieuTho!$I$9:$I$108,O35) -> 2 | Q35: =SQRT(P35) -> 1.4142136 | R35: =$S$7*POISSON(O35,$P$7,FALSE()) -> 2.2261068 | S35: =$S$7*NORMDIST(O35,$P$7,SQRT($P$7),FALSE()) -> 2.1556256 | T35: =IF(P35>0,(P35-R35)^2/P35,0) -> 0.025562143 | U35: =IF(P35>0,(P35-S35)^2/P35,0) -> 0.01210966
H36: 47 | I36: =COUNTIF(SoLieuTho!$F$9:$F$108,H36) -> 9 | J36: =SQRT(I36) -> 3 | K36: =$L$7*POISSON(H36,$I$7,FALSE()) -> 3.9426599 | L36: =$L$7*NORMDIST(H36,$I$7,SQRT($I$7),FALSE()) -> 4.1434337 | M36: =IF(I36>0,(I36-K36)^2/I36,0) -> 2.8418543 | N36: =IF(I36>0,(I36-L36)^2/I36,0) -> 2.6206929 | O36: 102 | P36: =COUNTIF(SoLieuTho!$I$9:$I$108,O36) -> 3 | Q36: =SQRT(P36) -> 1.7320508 | R36: =$S$7*POISSON(O36,$P$7,FALSE()) -> 2.4484992 | S36: =$S$7*NORMDIST(O36,$P$7,SQRT($P$7),FALSE()) -> 2.3711279 | T36: =IF(P36>0,(P36-R36)^2/P36,0) -> 0.10138436 | U36: =IF(P36>0,(P36-S36)^2/P36,0) -> 0.1318267
H37: 48 | I37: =COUNTIF(SoLieuTho!$F$9:$F$108,H37) -> 0 | J37: =SQRT(I37) -> 0 | K37: =$L$7*POISSON(H37,$I$7,FALSE()) -> 3.3857592 | L37: =$L$7*NORMDIST(H37,$I$7,SQRT($I$7),FALSE()) -> 3.557904 | M37: =IF(I37>0,(I37-K37)^2/I37,0) -> 0 | N37: =IF(I37>0,(I37-L37)^2/I37,0) -> 0 | O37: 103 | P37: =COUNTIF(SoLieuTho!$I$9:$I$108,O37) -> 2 | Q37: =SQRT(P37) -> 1.4142136 | R37: =$S$7*POISSON(O37,$P$7,FALSE()) -> 2.6669624 | S37: =$S$7*NORMDIST(O37,$P$7,SQRT($P$7),FALSE()) -> 2.5850299 | T37: =IF(P37>0,(P37-R37)^2/P37,0) -> 0.22241944 | U37: =IF(P37>0,(P37-S37)^2/P37,0) -> 0.17113002
H38: 49 | I38: =COUNTIF(SoLieuTho!$F$9:$F$108,H38) -> 4 | J38: =SQRT(I38) -> 2 | K38: =$L$7*POISSON(H38,$I$7,FALSE()) -> 2.8481835 | L38: =$L$7*NORMDIST(H38,$I$7,SQRT($I$7),FALSE()) -> 2.981893 | M38: =IF(I38>0,(I38-K38)^2/I38,0) -> 0.33167029 | N38: =IF(I38>0,(I38-L38)^2/I38,0) -> 0.25913549 | O38: 104 | P38: =COUNTIF(SoLieuTho!$I$9:$I$108,O38) -> 3 | Q38: =SQRT(P38) -> 1.7320508 | R38: =$S$7*POISSON(O38,$P$7,FALSE()) -> 2.8769857 | S38: =$S$7*NORMDIST(O38,$P$7,SQRT($P$7),FALSE()) -> 2.7932198 | T38: =IF(P38>0,(P38-R38)^2/P38,0) -> 0.0050441715 | U38: =IF(P38>0,(P38-S38)^2/P38,0) -> 0.014252685
H39: 50 | I39: =COUNTIF(SoLieuTho!$F$9:$F$108,H39) -> 1 | J39: =SQRT(I39) -> 1 | K39: =$L$7*POISSON(H39,$I$7,FALSE()) -> 2.3480425 | L39: =$L$7*NORMDIST(H39,$I$7,SQRT($I$7),FALSE()) -> 2.4392362 | M39: =IF(I39>0,(I39-K39)^2/I39,0) -> 1.8172186 | N39: =IF(I39>0,(I39-L39)^2/I39,0) -> 2.0714008 | O39: 105 | P39: =COUNTIF(SoLieuTho!$I$9:$I$108,O39) -> 4 | Q39: =SQRT(P39) -> 2 | R39: =$S$7*POISSON(O39,$P$7,FALSE()) -> 3.0739907 | S39: =$S$7*NORMDIST(O39,$P$7,SQRT($P$7),FALSE()) -> 2.9913937 | T39: =IF(P39>0,(P39-R39)^2/P39,0) -> 0.21437329 | U39: =IF(P39>0,(P39-S39)^2/P39,0) -> 0.25432165
... H53: 64 | I53: =COUNTIF(SoLieuTho!$F$9:$F$108,H53) -> 0 | J53: =SQRT(I53) -> 0 | K53: =$L$7*POISSON(H53,$I$7,FALSE()) -> 0.023007835 | L53: =$L$7*NORMDIST(H53,$I$7,SQRT($I$7),FALSE()) -> 0.011471963 | M53: =IF(I53>0,(I53-K53)^2/I53,0) -> 0 | N53: =IF(I53>0,(I53-L53)^2/I53,0) -> 0 | O53: 119 | P53: =COUNTIF(SoLieuTho!$I$9:$I$108,O53) -> 3 | Q53: =SQRT(P53) -> 1.7320508 | R53: =$S$7*POISSON(O53,$P$7,FALSE()) -> 2.9842355 | S53: =$S$7*NORMDIST(O53,$P$7,SQRT($P$7),FALSE()) -> 3.0631665 | T53: =IF(P53>0,(P53-R53)^2/P53,0) -> 8.2840083e-05 | U53: =IF(P53>0,(P53-S53)^2/P53,0) -> 0.0013300027
H54: Σ | I54: =SUM(I9:I53) -> 100 | K54: =SUM(K9:K53) -> 99.953476 | L54: =SUM(L9:L53) -> 99.950409 | M54: =SUM(M9:M53) -> 43.091911 | N54: =SUM(N9:N53) -> 44.562951 | O54: 120 | P54: =COUNTIF(SoLieuTho!$I$9:$I$108,O54) -> 3 | Q54: =SQRT(P54) -> 1.7320508 | R54: =$S$7*POISSON(O54,$P$7,FALSE()) -> 2.7900115 | S54: =$S$7*NORMDIST(O54,$P$7,SQRT($P$7),FALSE()) -> 2.8699421 | T54: =IF(P54>0,(P54-R54)^2/P54,0) -> 0.014698392 | U54: =IF(P54>0,(P54-S54)^2/P54,0) -> 0.0056383499
H55: bin | I55: =COUNTIF(I9:I53,">0") -> 28 | O55: 121 | P55: =COUNTIF(SoLieuTho!$I$9:$I$108,O55) -> 3 | Q55: =SQRT(P55) -> 1.7320508 | R55: =$S$7*POISSON(O55,$P$7,FALSE()) -> 2.586871 | S55: =$S$7*NORMDIST(O55,$P$7,SQRT($P$7),FALSE()) -> 2.6650454 | T55: =IF(P55>0,(P55-R55)^2/P55,0) -> 0.056891863 | U55: =IF(P55>0,(P55-S55)^2/P55,0) -> 0.037398195
O56: 122 | P56: =COUNTIF(SoLieuTho!$I$9:$I$108,O56) -> 1 | Q56: =SQRT(P56) -> 1 | R56: =$S$7*POISSON(O56,$P$7,FALSE()) -> 2.3788611 | S56: =$S$7*NORMDIST(O56,$P$7,SQRT($P$7),FALSE()) -> 2.4528163 | T56: =IF(P56>0,(P56-R56)^2/P56,0) -> 1.901258 | U56: =IF(P56>0,(P56-S56)^2/P56,0) -> 2.1106752
O57: 123 | P57: =COUNTIF(SoLieuTho!$I$9:$I$108,O57) -> 3 | Q57: =SQRT(P57) -> 1.7320508 | R57: =$S$7*POISSON(O57,$P$7,FALSE()) -> 2.1697921 | S57: =$S$7*NORMDIST(O57,$P$7,SQRT($P$7),FALSE()) -> 2.2374553 | T57: =IF(P57>0,(P57-R57)^2/P57,0) -> 0.22974839 | U57: =IF(P57>0,(P57-S57)^2/P57,0) -> 0.1938248
O58: 124 | P58: =COUNTIF(SoLieuTho!$I$9:$I$108,O58) -> 1 | Q58: =SQRT(P58) -> 1 | R58: =$S$7*POISSON(O58,$P$7,FALSE()) -> 1.9631369 | S58: =$S$7*NORMDIST(O58,$P$7,SQRT($P$7),FALSE()) -> 2.0228918 | T58: =IF(P58>0,(P58-R58)^2/P58,0) -> 0.92763268 | U58: =IF(P58>0,(P58-S58)^2/P58,0) -> 1.0463076
...

Sheet TocDoTichLuy
A1: TRƯỜNG ĐẠI HỌC KHOA HỌC TỰ NHIÊN, ĐHQG-HCM – KHOA VẬT LÝ – VẬT LÝ KỸ THUẬT
A2: TỐC ĐỘ ĐẾM TRUNG BÌNH TÍCH LŨY r_c(j)
A3: Mã hồ sơ: THVLHĐ-GM-N3-01 | Bài: Phân bố thống kê trong phân rã phóng xạ | Nhóm 3
A4: r_c(j) = Σᵢ₌₁ʲ Nᵢ / Σᵢ₌₁ʲ tᵢ (s⁻¹) – công thức (3)
A6: j | B6: Bộ 1 – Mức thấp (Phông) | C6: Bộ 2 – Mức trung bình (Ra-226) | D6: Bộ 3 – Mức cao (Ra-226)
A7: 1 | B7: =SUM(SoLieuTho!$C$9:C9)/SUM(SoLieuTho!$B$9:B9) -> 1 | C7: =SUM(SoLieuTho!$F$9:F9)/SUM(SoLieuTho!$B$9:B9) -> 4 | D7: =SUM(SoLieuTho!$I$9:I9)/SUM(SoLieuTho!$B$9:B9) -> 12.6
A8: 2 | B8: =SUM(SoLieuTho!$C$9:C10)/SUM(SoLieuTho!$B$9:B10) -> 0.95 | C8: =SUM(SoLieuTho!$F$9:F10)/SUM(SoLieuTho!$B$9:B10) -> 3.3 | D8: =SUM(SoLieuTho!$I$9:I10)/SUM(SoLieuTho!$B$9:B10) -> 12.05
A9: 3 | B9: =SUM(SoLieuTho!$C$9:C11)/SUM(SoLieuTho!$B$9:B11) -> 0.86666667 | C9: =SUM(SoLieuTho!$F$9:F11)/SUM(SoLieuTho!$B$9:B11) -> 3.3 | D9: =SUM(SoLieuTho!$I$9:I11)/SUM(SoLieuTho!$B$9:B11) -> 11.666667
A10: 4 | B10: =SUM(SoLieuTho!$C$9:C12)/SUM(SoLieuTho!$B$9:B12) -> 0.875 | C10: =SUM(SoLieuTho!$F$9:F12)/SUM(SoLieuTho!$B$9:B12) -> 3.325 | D10: =SUM(SoLieuTho!$I$9:I12)/SUM(SoLieuTho!$B$9:B12) -> 11.95
A11: 5 | B11: =SUM(SoLieuTho!$C$9:C13)/SUM(SoLieuTho!$B$9:B13) -> 0.8 | C11: =SUM(SoLieuTho!$F$9:F13)/SUM(SoLieuTho!$B$9:B13) -> 3.4 | D11: =SUM(SoLieuTho!$I$9:I13)/SUM(SoLieuTho!$B$9:B13) -> 12.24
A12: 6 | B12: =SUM(SoLieuTho!$C$9:C14)/SUM(SoLieuTho!$B$9:B14) -> 0.78333333 | C12: =SUM(SoLieuTho!$F$9:F14)/SUM(SoLieuTho!$B$9:B14) -> 3.6 | D12: =SUM(SoLieuTho!$I$9:I14)/SUM(SoLieuTho!$B$9:B14) -> 12.066667
A13: 7 | B13: =SUM(SoLieuTho!$C$9:C15)/SUM(SoLieuTho!$B$9:B15) -> 0.75714286 | C13: =SUM(SoLieuTho!$F$9:F15)/SUM(SoLieuTho!$B$9:B15) -> 3.5 | D13: =SUM(SoLieuTho!$I$9:I15)/SUM(SoLieuTho!$B$9:B15) -> 11.814286
A14: 8 | B14: =SUM(SoLieuTho!$C$9:C16)/SUM(SoLieuTho!$B$9:B16) -> 0.7625 | C14: =SUM(SoLieuTho!$F$9:F16)/SUM(SoLieuTho!$B$9:B16) -> 3.525 | D14: =SUM(SoLieuTho!$I$9:I16)/SUM(SoLieuTho!$B$9:B16) -> 11.65
A15: 9 | B15: =SUM(SoLieuTho!$C$9:C17)/SUM(SoLieuTho!$B$9:B17) -> 0.73333333 | C15: =SUM(SoLieuTho!$F$9:F17)/SUM(SoLieuTho!$B$9:B17) -> 3.5 | D15: =SUM(SoLieuTho!$I$9:I17)/SUM(SoLieuTho!$B$9:B17) -> 11.511111
A16: 10 | B16: =SUM(SoLieuTho!$C$9:C18)/SUM(SoLieuTho!$B$9:B18) -> 0.7 | C16: =SUM(SoLieuTho!$F$9:F18)/SUM(SoLieuTho!$B$9:B18) -> 3.48 | D16: =SUM(SoLieuTho!$I$9:I18)/SUM(SoLieuTho!$B$9:B18) -> 11.51
A17: 11 | B17: =SUM(SoLieuTho!$C$9:C19)/SUM(SoLieuTho!$B$9:B19) -> 0.69090909 | C17: =SUM(SoLieuTho!$F$9:F19)/SUM(SoLieuTho!$B$9:B19) -> 3.5545455 | D17: =SUM(SoLieuTho!$I$9:I19)/SUM(SoLieuTho!$B$9:B19) -> 11.372727
A18: 12 | B18: =SUM(SoLieuTho!$C$9:C20)/SUM(SoLieuTho!$B$9:B20) -> 0.66666667 | C18: =SUM(SoLieuTho!$F$9:F20)/SUM(SoLieuTho!$B$9:B20) -> 3.6083333 | D18: =SUM(SoLieuTho!$I$9:I20)/SUM(SoLieuTho!$B$9:B20) -> 11.216667
... A106: 100 | B106: =SUM(SoLieuTho!$C$9:C108)/SUM(SoLieuTho!$B$9:B108) -> 0.552 | C106: =SUM(SoLieuTho!$F$9:F108)/SUM(SoLieuTho!$B$9:B108) -> 4.122 | D106: =SUM(SoLieuTho!$I$9:I108)/SUM(SoLieuTho!$B$9:B108) -> 11.219

Sheet DoThi
A1: TRƯỜNG ĐẠI HỌC KHOA HỌC TỰ NHIÊN, ĐHQG-HCM – KHOA VẬT LÝ – VẬT LÝ KỸ THUẬT
A2: ĐỒ THỊ PHÂN BỐ TẦN SUẤT: THỰC NGHIỆM – POISSON – GAUSS
A3: Mã hồ sơ: THVLHĐ-GM-N3-01 | Bài: Phân bố thống kê trong phân rã phóng xạ | Nhóm 3
A4: Điểm đen: thực nghiệm (thanh sai số ±√O); đường liền: Poisson; đường đứt: Gauss.

Sheet MonteCarlo
A1: TRƯỜNG ĐẠI HỌC KHOA HỌC TỰ NHIÊN, ĐHQG-HCM – KHOA VẬT LÝ – VẬT LÝ KỸ THUẬT
A2: MÔ PHỎNG MONTE CARLO PHÂN BỐ POISSON (1000 LẦN THỬ)
A3: Mã hồ sơ: THVLHĐ-GM-N3-01 | Bài: Phân bố thống kê trong phân rã phóng xạ | Nhóm 3
A4: Sinh số ngẫu nhiên Poisson bằng numpy (seed = 2026) với µ = x̄ thực nghiệm; số liệu xuất từ analysis.py → montecarlo/mc_S*.csv (nhập tay, chữ xanh dương).
A6: Bộ 1 – Mức thấp (Phông) | F6: Bộ 2 – Mức trung bình (Ra-226) | K6: Bộ 3 – Mức cao (Ra-226)
A7: µ (thực nghiệm) | C7: =ThongKe!C10 -> 5.52 | F7: µ (thực nghiệm) | H7: =ThongKe!D10 -> 41.22 | K7: µ (thực nghiệm) | M7: =ThongKe!E10 -> 112.19
A8: k | B8: Tần suất MC | C8: E Poisson | D8: (O−E)²/O | F8: k | G8: Tần suất MC | H8: E Poisson | I8: (O−E)²/O | K8: k | L8: Tần suất MC | M8: E Poisson | N8: (O−E)²/O
A9: 0 | B9: 4 | C9: =SUM($B$9:$B$23)*POISSON(A9,$C$7,FALSE()) -> 4.0058479 | D9: =IF(B9>0,(B9-C9)^2/B9,0) -> 8.5496067e-06 | F9: 21 | G9: 1 | H9: =SUM($G$9:$G$52)*POISSON(F9,$H$7,FALSE()) -> 0.20291085 | I9: =IF(G9>0,(G9-H9)^2/G9,0) -> 0.63535111 | K9: 79 | L9: 1 | M9: =SUM($L$9:$L$74)*POISSON(K9,$M$7,FALSE()) -> 0.18674201 | N9: =IF(L9>0,(L9-M9)^2/L9,0) -> 0.66138856
A10: 1 | B10: 25 | C10: =SUM($B$9:$B$23)*POISSON(A10,$C$7,FALSE()) -> 22.112281 | D10: =IF(B10>0,(B10-C10)^2/B10,0) -> 0.33355692 | F10: 22 | G10: 0 | H10: =SUM($G$9:$G$52)*POISSON(F10,$H$7,FALSE()) -> 0.38018116 | I10: =IF(G10>0,(G10-H10)^2/G10,0) -> 0 | K10: 80 | L10: 0 | M10: =SUM($L$9:$L$74)*POISSON(K10,$M$7,FALSE()) -> 0.26188233 | N10: =IF(L10>0,(L10-M10)^2/L10,0) -> 0
A11: 2 | B11: 47 | C11: =SUM($B$9:$B$23)*POISSON(A11,$C$7,FALSE()) -> 61.029895 | D11: =IF(B11>0,(B11-C11)^2/B11,0) -> 4.1880413 | F11: 23 | G11: 0 | H11: =SUM($G$9:$G$52)*POISSON(F11,$H$7,FALSE()) -> 0.68135075 | I11: =IF(G11>0,(G11-H11)^2/G11,0) -> 0 | K11: 81 | L11: 0 | M11: =SUM($L$9:$L$74)*POISSON(K11,$M$7,FALSE()) -> 0.36272319 | N11: =IF(L11>0,(L11-M11)^2/L11,0) -> 0
A12: 3 | B12: 105 | C12: =SUM($B$9:$B$23)*POISSON(A12,$C$7,FALSE()) -> 112.29501 | D12: =IF(B12>0,(B12-C12)^2/B12,0) -> 0.50682964 | F12: 24 | G12: 0 | H12: =SUM($G$9:$G$52)*POISSON(F12,$H$7,FALSE()) -> 1.1702199 | I12: =IF(G12>0,(G12-H12)^2/G12,0) -> 0 | K12: 82 | L12: 1 | M12: =SUM($L$9:$L$74)*POISSON(K12,$M$7,FALSE()) -> 0.49626725 | N12: =IF(L12>0,(L12-M12)^2/L12,0) -> 0.25374668
A13: 4 | B13: 155 | C13: =SUM($B$9:$B$23)*POISSON(A13,$C$7,FALSE()) -> 154.96711 | D13: =IF(B13>0,(B13-C13)^2/B13,0) -> 6.9797735e-06 | F13: 25 | G13: 1 | H13: =SUM($G$9:$G$52)*POISSON(F13,$H$7,FALSE()) -> 1.9294586 | I13: =IF(G13>0,(G13-H13)^2/G13,0) -> 0.86389328 | K13: 83 | L13: 0 | M13: =SUM($L$9:$L$74)*POISSON(K13,$M$7,FALSE()) -> 0.67079787 | N13: =IF(L13>0,(L13-M13)^2/L13,0) -> 0
A14: 5 | B14: 162 | C14: =SUM($B$9:$B$23)*POISSON(A14,$C$7,FALSE()) -> 171.08369 | D14: =IF(B14>0,(B14-C14)^2/B14,0) -> 0.50934185 | F14: 26 | G14: 0 | H14: =SUM($G$9:$G$52)*POISSON(F14,$H$7,FALSE()) -> 3.058934 | I14: =IF(G14>0,(G14-H14)^2/G14,0) -> 0 | K14: 84 | L14: 0 | M14: =SUM($L$9:$L$74)*POISSON(K14,$M$7,FALSE()) -> 0.89591444 | N14: =IF(L14>0,(L14-M14)^2/L14,0) -> 0
A15: 6 | B15: 159 | C15: =SUM($B$9:$B$23)*POISSON(A15,$C$7,FALSE()) -> 157.39699 | D15: =IF(B15>0,(B15-C15)^2/B15,0) -> 0.016161213 | F15: 27 | G15: 5 | H15: =SUM($G$9:$G$52)*POISSON(F15,$H$7,FALSE()) -> 4.6699725 | I15: =IF(G15>0,(G15-H15)^2/G15,0) -> 0.021783626 | K15: 85 | L15: 0 | M15: =SUM($L$9:$L$74)*POISSON(K15,$M$7,FALSE()) -> 1.1825017 | N15: =IF(L15>0,(L15-M15)^2/L15,0) -> 0
A16: 7 | B16: 135 | C16: =SUM($B$9:$B$23)*POISSON(A16,$C$7,FALSE()) -> 124.11877 | D16: =IF(B16>0,(B16-C16)^2/B16,0) -> 0.87704547 | F16: 28 | G16: 7 | H16: =SUM($G$9:$G$52)*POISSON(F16,$H$7,FALSE()) -> 6.8748667 | I16: =IF(G16>0,(G16-H16)^2/G16,0) -> 0.002236906 | K16: 86 | L16: 1 | M16: =SUM($L$9:$L$74)*POISSON(K16,$M$7,FALSE()) -> 1.5426147 | N16: =IF(L16>0,(L16-M16)^2/L16,0) -> 0.29443068
A17: 8 | B17: 86 | C17: =SUM($B$9:$B$23)*POISSON(A17,$C$7,FALSE()) -> 85.641952 | D17: =IF(B17>0,(B17-C17)^2/B17,0) -> 0.0014906773 | F17: 29 | G17: 10 | H17: =SUM($G$9:$G$52)*POISSON(F17,$H$7,FALSE()) -> 9.7717933 | I17: =IF(G17>0,(G17-H17)^2/G17,0) -> 0.0052078301 | K17: 87 | L17: 2 | M17: =SUM($L$9:$L$74)*POISSON(K17,$M$7,FALSE()) -> 1.9892637 | N17: =IF(L17>0,(L17-M17)^2/L17,0) -> 5.7634379e-05
A18: 9 | B18: 55 | C18: =SUM($B$9:$B$23)*POISSON(A18,$C$7,FALSE()) -> 52.527064 | D18: =IF(B18>0,(B18-C18)^2/B18,0) -> 0.11118932 | F18: 30 | G18: 11 | H18: =SUM($G$9:$G$52)*POISSON(F18,$H$7,FALSE()) -> 13.426444 | I18: =IF(G18>0,(G18-H18)^2/G18,0) -> 0.53523913 | K18: 88 | L18: 3 | M18: =SUM($L$9:$L$74)*POISSON(K18,$M$7,FALSE()) -> 2.5360851 | N18: =IF(L18>0,(L18-M18)^2/L18,0) -> 0.071739003
A19: 10 | B19: 35 | C19: =SUM($B$9:$B$23)*POISSON(A19,$C$7,FALSE()) -> 28.994939 | D19: =IF(B19>0,(B19-C19)^2/B19,0) -> 1.0303072 | F19: 31 | G19: 20 | H19: =SUM($G$9:$G$52)*POISSON(F19,$H$7,FALSE()) -> 17.852839 | I19: =IF(G19>0,(G19-H19)^2/G19,0) -> 0.23051493 | K19: 89 | L19: 3 | M19: =SUM($L$9:$L$74)*POISSON(K19,$M$7,FALSE()) -> 3.196892 | N19: =IF(L19>0,(L19-M19)^2/L19,0) -> 0.012922157
A20: 11 | B20: 19 | C20: =SUM($B$9:$B$23)*POISSON(A20,$C$7,FALSE()) -> 14.550188 | D20: =IF(B20>0,(B20-C20)^2/B20,0) -> 1.0421489 | F20: 32 | G20: 25 | H20: =SUM($G$9:$G$52)*POISSON(F20,$H$7,FALSE()) -> 22.996689 | I20: =IF(G20>0,(G20-H20)^2/G20,0) -> 0.16053024 | K20: 90 | L20: 4 | M20: =SUM($L$9:$L$74)*POISSON(K20,$M$7,FALSE()) -> 3.9851035 | N20: =IF(L20>0,(L20-M20)^2/L20,0) -> 5.5476292e-05
... A23: 14 | B23: 2 | C23: =SUM($B$9:$B$23)*POISSON(A23,$C$7,FALSE()) -> 1.120555 | D23: =IF(B23>0,(B23-C23)^2/B23,0) -> 0.38671171 | F23: 35 | G23: 50 | H23: =SUM($G$9:$G$52)*POISSON(F23,$H$7,FALSE()) -> 41.013645 | I23: =IF(G23>0,(G23-H23)^2/G23,0) -> 1.6150915 | K23: 93 | L23: 9 | M23: =SUM($L$9:$L$74)*POISSON(K23,$M$7,FALSE()) -> 7.2275297 | N23: =IF(L23>0,(L23-M23)^2/L23,0) -> 0.34907234
F24: 36 | G24: 51 | H24: =SUM($G$9:$G$52)*POISSON(F24,$H$7,FALSE()) -> 46.960624 | I24: =IF(G24>0,(G24-H24)^2/G24,0) -> 0.31993259 | K24: 94 | L24: 6 | M24: =SUM($L$9:$L$74)*POISSON(K24,$M$7,FALSE()) -> 8.6261335 | N24: =IF(L24>0,(L24-M24)^2/L24,0) -> 1.1494296
F25: 37 | G25: 60 | H25: =SUM($G$9:$G$52)*POISSON(F25,$H$7,FALSE()) -> 52.316673 | I25: =IF(G25>0,(G25-H25)^2/G25,0) -> 0.98389189 | K25: 95 | L25: 10 | M25: =SUM($L$9:$L$74)*POISSON(K25,$M$7,FALSE()) -> 10.18701 | N25: =IF(L25>0,(L25-M25)^2/L25,0) -> 0.0034972633
F26: 38 | G26: 58 | H26: =SUM($G$9:$G$52)*POISSON(F26,$H$7,FALSE()) -> 56.749823 | I26: =IF(G26>0,(G26-H26)^2/G26,0) -> 0.026947298 | K26: 96 | L26: 15 | M26: =SUM($L$9:$L$74)*POISSON(K26,$M$7,FALSE()) -> 11.905006 | N26: =IF(L26>0,(L26-M26)^2/L26,0) -> 0.638599
F27: 39 | G27: 63 | H27: =SUM($G$9:$G$52)*POISSON(F27,$H$7,FALSE()) -> 59.980197 | I27: =IF(G27>0,(G27-H27)^2/G27,0) -> 0.14474935 | K27: 97 | L27: 22 | M27: =SUM($L$9:$L$74)*POISSON(K27,$M$7,FALSE()) -> 13.769306 | N27: =IF(L27>0,(L27-M27)^2/L27,0) -> 3.0792875
F28: 40 | G28: 57 | H28: =SUM($G$9:$G$52)*POISSON(F28,$H$7,FALSE()) -> 61.809593 | I28: =IF(G28>0,(G28-H28)^2/G28,0) -> 0.40582784 | K28: 98 | L28: 24 | M28: =SUM($L$9:$L$74)*POISSON(K28,$M$7,FALSE()) -> 15.763045 | N28: =IF(L28>0,(L28-M28)^2/L28,0) -> 2.826976
F29: 41 | G29: 57 | H29: =SUM($G$9:$G$52)*POISSON(F29,$H$7,FALSE()) -> 62.141254 | I29: =IF(G29>0,(G29-H29)^2/G29,0) -> 0.46372803 | K29: 99 | L29: 18 | M29: =SUM($L$9:$L$74)*POISSON(K29,$M$7,FALSE()) -> 17.863192 | N29: =IF(L29>0,(L29-M29)^2/L29,0) -> 0.0010397963
F30: 42 | G30: 62 | H30: =SUM($G$9:$G$52)*POISSON(F30,$H$7,FALSE()) -> 60.987203 | I30: =IF(G30>0,(G30-H30)^2/G30,0) -> 0.016544493 | K30: 100 | L30: 14 | M30: =SUM($L$9:$L$74)*POISSON(K30,$M$7,FALSE()) -> 20.040715 | N30: =IF(L30>0,(L30-M30)^2/L30,0) -> 2.606446
F31: 43 | G31: 52 | H31: =SUM($G$9:$G$52)*POISSON(F31,$H$7,FALSE()) -> 58.462616 | I31: =IF(G31>0,(G31-H31)^2/G31,0) -> 0.80318089 | K31: 101 | L31: 21 | M31: =SUM($L$9:$L$74)*POISSON(K31,$M$7,FALSE()) -> 22.261068 | N31: =IF(L31>0,(L31-M31)^2/L31,0) -> 0.075728219
F32: 44 | G32: 49 | H32: =SUM($G$9:$G$52)*POISSON(F32,$H$7,FALSE()) -> 54.768842 | I32: =IF(G32>0,(G32-H32)^2/G32,0) -> 0.67917417 | K32: 102 | L32: 20 | M32: =SUM($L$9:$L$74)*POISSON(K32,$M$7,FALSE()) -> 24.484992 | N32: =IF(L32>0,(L32-M32)^2/L32,0) -> 1.0057578
F33: 45 | G33: 48 | H33: =SUM($G$9:$G$52)*POISSON(F33,$H$7,FALSE()) -> 50.168259 | I33: =IF(G33>0,(G33-H33)^2/G33,0) -> 0.09794473 | K33: 103 | L33: 26 | M33: =SUM($L$9:$L$74)*POISSON(K33,$M$7,FALSE()) -> 26.669624 | N33: =IF(L33>0,(L33-M33)^2/L33,0) -> 0.017246023
F34: 46 | G34: 54 | H34: =SUM($G$9:$G$52)*POISSON(F34,$H$7,FALSE()) -> 44.955123 | I34: =IF(G34>0,(G34-H34)^2/G34,0) -> 1.5149965 | K34: 104 | L34: 29 | M34: =SUM($L$9:$L$74)*POISSON(K34,$M$7,FALSE()) -> 28.769857 | N34: =IF(L34>0,(L34-M34)^2/L34,0) -> 0.0018264047
F35: 47 | G35: 31 | H35: =SUM($G$9:$G$52)*POISSON(F35,$H$7,FALSE()) -> 39.426599 | I35: =IF(G35>0,(G35-H35)^2/G35,0) -> 2.2905668 | K35: 105 | L35: 28 | M35: =SUM($L$9:$L$74)*POISSON(K35,$M$7,FALSE()) -> 30.739907 | N35: =IF(L35>0,(L35-M35)^2/L35,0) -> 0.26811044
... F52: 64 | G52: 1 | H52: =SUM($G$9:$G$52)*POISSON(F52,$H$7,FALSE()) -> 0.23007835 | I52: =IF(G52>0,(G52-H52)^2/G52,0) -> 0.59277935 | K52: 122 | L52: 19 | M52: =SUM($L$9:$L$74)*POISSON(K52,$M$7,FALSE()) -> 23.788611 | N52: =IF(L52>0,(L52-M52)^2/L52,0) -> 1.206884
K53: 123 | L53: 22 | M53: =SUM($L$9:$L$74)*POISSON(K53,$M$7,FALSE()) -> 21.697921 | N53: =IF(L53>0,(L53-M53)^2/L53,0) -> 0.0041478073
K54: 124 | L54: 16 | M54: =SUM($L$9:$L$74)*POISSON(K54,$M$7,FALSE()) -> 19.631369 | N54: =IF(L54>0,(L54-M54)^2/L54,0) -> 0.82417753
K55: 125 | L55: 21 | M55: =SUM($L$9:$L$74)*POISSON(K55,$M$7,FALSE()) -> 17.619546 | N55: =IF(L55>0,(L55-M55)^2/L55,0) -> 0.54416512
K56: 126 | L56: 12 | M56: =SUM($L$9:$L$74)*POISSON(K56,$M$7,FALSE()) -> 15.688388 | N56: =IF(L56>0,(L56-M56)^2/L56,0) -> 1.1336839
K57: 127 | L57: 17 | M57: =SUM($L$9:$L$74)*POISSON(K57,$M$7,FALSE()) -> 13.8589 | N57: =IF(L57>0,(L57-M57)^2/L57,0) -> 0.58038302
K58: 128 | L58: 10 | M58: =SUM($L$9:$L$74)*POISSON(K58,$M$7,FALSE()) -> 12.147109 | N58: =IF(L58>0,(L58-M58)^2/L58,0) -> 0.46100771
K59: 129 | L59: 11 | M59: =SUM($L$9:$L$74)*POISSON(K59,$M$7,FALSE()) -> 10.564218 | N59: =IF(L59>0,(L59-M59)^2/L59,0) -> 0.017264155
...

Sheet KetQua
A1: TRƯỜNG ĐẠI HỌC KHOA HỌC TỰ NHIÊN, ĐHQG-HCM – KHOA VẬT LÝ – VẬT LÝ KỸ THUẬT
A2: TỔNG HỢP KẾT QUẢ ĐO
A3: Mã hồ sơ: THVLHĐ-GM-N3-01 | Bài: Phân bố thống kê trong phân rã phóng xạ | Nhóm 3
A5: STT | B5: Đại lượng (k = 1) | C5: Bộ 1 – Mức thấp (Phông) | E5: Bộ 2 – Mức trung bình (Ra-226) | G5: Bộ 3 – Mức cao (Ra-226)
C6: Giá trị | D6: u | E6: Giá trị | F6: u | G6: Giá trị | H6: u
A7: 1 | B7: Số đếm trung bình trong 10 s, x̄ | C7: =ThongKe!C10 -> 5.52 | D7: =ThongKe!C13 -> 0.24637985 | E7: =ThongKe!D10 -> 41.22 | F7: =ThongKe!D13 -> 0.70375329 | G7: =ThongKe!E10 -> 112.19 | H7: =ThongKe!E13 -> 1.1348203
A8: 2 | B8: Tốc độ đếm R (s⁻¹) | C8: =ThongKe!C20 -> 0.552 | D8: =ThongKe!C21 -> 0.024637985 | E8: =ThongKe!D20 -> 4.122 | F8: =ThongKe!D21 -> 0.070375329 | G8: =ThongKe!E20 -> 11.219 | H8: =ThongKe!E21 -> 0.11348203
A9: 3 | B9: Phép đo dài quy về 10 s | C9: =ThongKe!C24 -> 4.5 | D9: =ThongKe!C25 -> 0.67082039 | E9: =ThongKe!D24 -> 43.7 | F9: =ThongKe!D25 -> 2.0904545 | G9: =ThongKe!E24 -> 108.5 | H9: =ThongKe!E25 -> 3.2939338
A10: 4 | B10: Độ lệch chuẩn thực nghiệm s | C10: =ThongKe!C11 -> 2.4637985 | E10: =ThongKe!D11 -> 7.0375329 | G10: =ThongKe!E11 -> 11.348203
A11: 5 | B11: Độ lệch chuẩn Poisson √x̄ | C11: =ThongKe!C14 -> 2.349468 | E11: =ThongKe!D14 -> 6.4202804 | G11: =ThongKe!E14 -> 10.591978
A12: 6 | B12: Chỉ số phân tán D = s²/x̄ | C12: =ThongKe!C16 -> 1.0996926 | E12: =ThongKe!D16 -> 1.2015252 | G12: =ThongKe!E16 -> 1.1478894
A13: 7 | B13: p-value kiểm định phân tán | C13: =ThongKe!C18 -> 0.46760639 | E13: =ThongKe!D18 -> 0.1678645 | G13: =ThongKe!E18 -> 0.29831169
A14: 8 | B14: Chỉ số z (10 s so với 100 s) | C14: =ThongKe!C29 -> -1.4273023 | E14: =ThongKe!D29 -> 1.1243416 | G14: =ThongKe!E29 -> -1.0591466
A15: 9 | B15: χ² Poisson (công thức 5) / ν | C15: =ThongKe!C41 -> 28.252044 | D15: =ThongKe!C44 -> 10 | E15: =ThongKe!D41 -> 43.091911 | F15: =ThongKe!D44 -> 27 | G15: =ThongKe!E41 -> 34.111204 | H15: =ThongKe!E44 -> 40
A16: 10 | B16: χ² Gauss (công thức 5) / ν | C16: =ThongKe!C42 -> 35.547824 | D16: =ThongKe!C44 -> 10 | E16: =ThongKe!D42 -> 44.562951 | F16: =ThongKe!D44 -> 27 | G16: =ThongKe!E42 -> 33.448438 | H16: =ThongKe!E44 -> 40
A17: 11 | B17: Phân bố phù hợp hơn | C17: =ThongKe!C49 -> Poisson | E17: =ThongKe!D49 -> Poisson | G17: =ThongKe!E49 -> Gauss
A18: 12 | B18: Xác suất ≥ 1 lần lệch cực đại trong 100 lần | C18: =ThongKe!C37 -> 0.67826682 | E18: =ThongKe!D37 -> 0.54511219 | G18: =ThongKe!E37 -> 0.11486643
A20: χ² PEARSON (GỘP BIN SAO CHO E ≥ 5) – tính bằng analysis.py, dùng để đối chiếu
B21: Phân bố | C21: χ² | D21: ν | E21: p
B22: Bộ 1 – Mức thấp (Phông) – Poisson | C22: 11.064668 | D22: 7 | E22: =CHIDIST(C22,D22) -> 0.135823
B23: Bộ 1 – Mức thấp (Phông) – Gauss | C23: 10.475861 | D23: 6 | E23: =CHIDIST(C23,D23) -> 0.10599047
B24: Bộ 2 – Mức trung bình (Ra-226) – Poisson | C24: 17.616211 | D24: 13 | E24: =CHIDIST(C24,D24) -> 0.17264275
B25: Bộ 2 – Mức trung bình (Ra-226) – Gauss | C25: 18.413457 | D25: 13 | E25: =CHIDIST(C25,D25) -> 0.14244227
B26: Bộ 3 – Mức cao (Ra-226) – Poisson | C26: 10.200438 | D26: 13 | E26: =CHIDIST(C26,D26) -> 0.67746747
B27: Bộ 3 – Mức cao (Ra-226) – Gauss | C27: 16.876639 | D27: 14 | E27: =CHIDIST(C27,D27) -> 0.26281144
A29: NHẬN XÉT
A30: 1. r_c(j) của cả ba bộ hội tụ về giá trị trung bình và nằm trong dải ±1σ Poisson sau ~20–30 lần đo: quá trình đếm dừng trong suốt thời gian đo.
A31: 2. s ≈ √x̄ (D = 1,10; 1,20; 1,15; p-value > 0,05): phương sai phù hợp phân bố Poisson.
A32: 3. Kết quả phép đo 100 s phù hợp với trung bình 100 lần đo 10 s trong khoảng 1,5σ (|z| ≤ 1,43).
A33: 4. Bộ mức thấp: độ lệch lớn nhất (x = 12, ≈ 2,8σ) có xác suất xuất hiện ≈ 68% trong 100 lần đo: hệ đếm hoạt động bình thường.
A34: 5. Ở µ ≈ 41 Poisson cho χ² nhỏ hơn Gauss một chút; ở µ ≈ 112 hai phân bố gần như trùng nhau: xấp xỉ Gauss chỉ tốt khi µ lớn.
A35: 6. χ² theo công thức (5) bị phóng đại khi O nhỏ (σ = √O); χ² Pearson gộp bin cho p > 0,1 ở cả ba bộ.

Sheet PhanCong
A1: TRƯỜNG ĐẠI HỌC KHOA HỌC TỰ NHIÊN, ĐHQG-HCM – KHOA VẬT LÝ – VẬT LÝ KỸ THUẬT
A2: BẢNG PHÂN CÔNG CÔNG VIỆC – NHÓM 3
A3: Mã hồ sơ: THVLHĐ-GM-N3-01 | Bài: Phân bố thống kê trong phân rã phóng xạ | Nhóm 3
A4: Nội dung phân công là đề xuất (nền vàng), nhóm cần điều chỉnh theo thực tế.
A6: STT | B6: Họ và tên | C6: MSSV | D6: Nhiệm vụ | E6: Mức độ hoàn thành | F6: Ghi chú
A7: 1 | B7: Phạm Việt Linh | C7: 24130044 | D7: Lắp đặt hệ đo, đo Bộ 1 (mức thấp) | E7: 100%
A8: 2 | B8: Lê Quốc Long | C8: 24130048 | D8: Tổng hợp số liệu, xử lý thống kê, soạn báo cáo | E8: 100%
A9: 3 | B9: Ngô Đặng Tuấn Long | C9: 24130049 | D9: Đo Bộ 2, ghi điều kiện đo | E9: 100%
A10: 4 | B10: Dương Quốc Huy | C10: 24130103 | D10: Đo Bộ 3, phép đo dài 100 s | E10: 100%
A11: 5 | B11: Trần Trí Dũng | C11: 24130162 | D11: Vẽ đồ thị phân bố tần suất, thanh sai số | E11: 100%
A12: 6 | B12: Nguyễn Trần Nhiên Đăng | C12: 24130147 | D12: Tính χ², so sánh Poisson – Gauss | E12: 100%
A13: 7 | B13: Lê Anh Đức | C13: 24130157 | D13: Mô phỏng Monte Carlo | E13: 100%
A14: 8 | B14: Trần Thanh Đức | C14: 24130159 | D14: Cơ sở lý thuyết, câu hỏi tìm hiểu thêm | E14: 100%
A15: 9 | B15: Nguyễn Vũ Nhật Minh | C15: 24130218 | D15: Kiểm tra, biên tập báo cáo | E15: 100%
